Workbook

Sheet Score Sheet
A1: Ordering | B1: Experiment Name | C1: Day of Experiment | D1: TIFF Name | E1: Link to Image | F1: KP score | G1: LW score | H1: KC score | I1: XP score | J1: # of Graders Scored | K1: 4/4 Graders Agree? | L1: 3/4 graders agree | M1: 2/4 graders agree | N1: 50/50 Split | O1: T/F if na of 50/50 Split | P1: Final Score | Q1: Mode | R1: Notes
A2: 0 | B2: =COUNTA(B3:B5499) -> 3971 | C2: =COUNTA(C3:C5499) -> 3971 | D2: =COUNTA(D3:D5726) -> 3971 | E2: =COUNTA(E3:E5499) -> 3971 | F2: =COUNTA(F3:F5499) -> 2128 | G2: =COUNTA(G3:G5499) -> 3928 | H2: =COUNTA(H3:H5499) -> 3670 | I2: =COUNTA(I3:I5499) -> 3127
A3: 1 | B3: Alt Prime Rd. 1 | C3: 1 | D3: 20220505mouse1_OD_R_2_0_0000002_Structure_0001D1 | E3: https://drive.google.com/file/d/16tNrWXMBbGIJLVTsPcJhp7jgVACRNegl/view?usp=sharing | F3: 2 | G3: 2 | H3: 2 | I3: 2 | J3: =COUNTA(F3:I3) -> 4 | K3: {=IFS(OR(F3="",G3="",H3="",I3=""), FALSE, OR(F3<>G3, F3<>H3, F3<>I3, G3<>H3, G3<>I3, H3<>I3), FALSE, OR(F3=G3, F3=H3, F3=I3, G3=H3,G3=I3, H3=I3), TRUE)} -> TRUE | L3: =OR(AND(F3=G3,G3=H3),AND(H3=I3,F3=I3),AND(G3=H3,H3=I3), AND(F3=G3,G3=I3)) -> TRUE | M3: =OR(F3=G3,G3=H3,H3=I3,F3=I3, G3=I3, F3=H3) -> TRUE | N3: =AND(K3=FALSE,L3=FALSE,IF(COUNTIF(F3:I3,F3)>1,TRUE,FALSE),IF(COUNTIF(F3:I3,G3)>1,TRUE,FALSE),IF(COUNTIF(F3:I3,H3)>1,TRUE,FALSE),IF(COUNTIF(F3:I3,I3)>1,TRUE,FALSE)) -> FALSE | O3: =AND(N3=TRUE, COUNTIF(F3:I3, "100")) -> FALSE | P3: {=IFS(K3=TRUE, Q3, L3=TRUE, Q3, N3=FALSE, Q3, F3=G3, Q3, F3=Q3, Q3)} -> 2 | Q3: =MODE(F3:I3) -> 2
A4: 2 | B4: Alt Prime Rd. 1 | C4: 1 | D4: 20220505mouse1_OD_R_2_0_0000002_Structure_0002D1 | E4: https://drive.google.com/file/d/1E6yqvKyP7535UL_GEGFwMB_LsfavBr5p/view?usp=sharing | F4: 2 | G4: 2 | H4: 2 | I4: 2 | J4: =COUNTA(F4:I4) -> 4 | K4: {=IFS(OR(F4="",G4="",H4="",I4=""), FALSE, OR(F4<>G4, F4<>H4, F4<>I4, G4<>H4, G4<>I4, H4<>I4), FALSE, OR(F4=G4, F4=H4, F4=I4, G4=H4,G4=I4, H4=I4), TRUE)} -> TRUE | L4: =OR(AND(F4=G4,G4=H4),AND(H4=I4,F4=I4),AND(G4=H4,H4=I4), AND(F4=G4,G4=I4)) -> TRUE | M4: =OR(F4=G4,G4=H4,H4=I4,F4=I4, G4=I4, F4=H4) -> TRUE | N4: =AND(K4=FALSE,L4=FALSE,IF(COUNTIF(F4:I4,F4)>1,TRUE,FALSE),IF(COUNTIF(F4:I4,G4)>1,TRUE,FALSE),IF(COUNTIF(F4:I4,H4)>1,TRUE,FALSE),IF(COUNTIF(F4:I4,I4)>1,TRUE,FALSE)) -> FALSE | O4: =AND(N4=TRUE, COUNTIF(F4:I4, "100")) -> FALSE | P4: {=IFS(K4=TRUE, Q4, L4=TRUE, Q4, N4=FALSE, Q4, F4=G4, Q4, F4=Q4, Q4)} -> 2 | Q4: =MODE(F4:I4) -> 2
A5: 3 | B5: Alt Prime Rd. 1 | C5: 1 | D5: 20220505mouse1_OD_R_2_0_0000002_Structure_0003D1 | E5: https://drive.google.com/file/d/1O76_BFFW5AhLFKfsdh3fRPvqEhQv1Vrg/view?usp=sharing | F5: 2 | G5: 2 | H5: 2 | I5: 2 | J5: =COUNTA(F5:I5) -> 4 | K5: {=IFS(OR(F5="",G5="",H5="",I5=""), FALSE, OR(F5<>G5, F5<>H5, F5<>I5, G5<>H5, G5<>I5, H5<>I5), FALSE, OR(F5=G5, F5=H5, F5=I5, G5=H5,G5=I5, H5=I5), TRUE)} -> TRUE | L5: =OR(AND(F5=G5,G5=H5),AND(H5=I5,F5=I5),AND(G5=H5,H5=I5), AND(F5=G5,G5=I5)) -> TRUE | M5: =OR(F5=G5,G5=H5,H5=I5,F5=I5, G5=I5, F5=H5) -> TRUE | N5: =AND(K5=FALSE,L5=FALSE,IF(COUNTIF(F5:I5,F5)>1,TRUE,FALSE),IF(COUNTIF(F5:I5,G5)>1,TRUE,FALSE),IF(COUNTIF(F5:I5,H5)>1,TRUE,FALSE),IF(COUNTIF(F5:I5,I5)>1,TRUE,FALSE)) -> FALSE | O5: =AND(N5=TRUE, COUNTIF(F5:I5, "100")) -> FALSE | P5: {=IFS(K5=TRUE, Q5, L5=TRUE, Q5, N5=FALSE, Q5, F5=G5, Q5, F5=Q5, Q5)} -> 2 | Q5: =MODE(F5:I5) -> 2
A6: 4 | B6: Alt Prime Rd. 1 | C6: 1 | D6: 20220505mouse1_OD_R_2_0_0000002_Structure_0004D1 | E6: https://drive.google.com/file/d/17InvZsVYM3wxw1CQ68Jj7U-6UGwp2CEY/view?usp=sharing | F6: 2 | G6: 2 | H6: 2 | I6: 2 | J6: =COUNTA(F6:I6) -> 4 | K6: {=IFS(OR(F6="",G6="",H6="",I6=""), FALSE, OR(F6<>G6, F6<>H6, F6<>I6, G6<>H6, G6<>I6, H6<>I6), FALSE, OR(F6=G6, F6=H6, F6=I6, G6=H6,G6=I6, H6=I6), TRUE)} -> TRUE | L6: =OR(AND(F6=G6,G6=H6),AND(H6=I6,F6=I6),AND(G6=H6,H6=I6), AND(F6=G6,G6=I6)) -> TRUE | M6: =OR(F6=G6,G6=H6,H6=I6,F6=I6, G6=I6, F6=H6) -> TRUE | N6: =AND(K6=FALSE,L6=FALSE,IF(COUNTIF(F6:I6,F6)>1,TRUE,FALSE),IF(COUNTIF(F6:I6,G6)>1,TRUE,FALSE),IF(COUNTIF(F6:I6,H6)>1,TRUE,FALSE),IF(COUNTIF(F6:I6,I6)>1,TRUE,FALSE)) -> FALSE | O6: =AND(N6=TRUE, COUNTIF(F6:I6, "100")) -> FALSE | P6: {=IFS(K6=TRUE, Q6, L6=TRUE, Q6, N6=FALSE, Q6, F6=G6, Q6, F6=Q6, Q6)} -> 2 | Q6: =MODE(F6:I6) -> 2
A7: 5 | B7: Alt Prime Rd. 1 | C7: 1 | D7: 20220505mouse1_OD_R_4_0_0000009_Structure_0001D1 | E7: https://drive.google.com/file/d/1oQHTMcFO_RZ4HjMNfRzamPrpeFFis1oU/view?usp=sharing | F7: 1 | G7: 0.5 | H7: 1 | I7: 0.5 | J7: =COUNTA(F7:I7) -> 4 | K7: {=IFS(OR(F7="",G7="",H7="",I7=""), FALSE, OR(F7<>G7, F7<>H7, F7<>I7, G7<>H7, G7<>I7, H7<>I7), FALSE, OR(F7=G7, F7=H7, F7=I7, G7=H7,G7=I7, H7=I7), TRUE)} -> FALSE | L7: =OR(AND(F7=G7,G7=H7),AND(H7=I7,F7=I7),AND(G7=H7,H7=I7), AND(F7=G7,G7=I7)) -> FALSE | M7: =OR(F7=G7,G7=H7,H7=I7,F7=I7, G7=I7, F7=H7) -> TRUE | N7: =AND(K7=FALSE,L7=FALSE,IF(COUNTIF(F7:I7,F7)>1,TRUE,FALSE),IF(COUNTIF(F7:I7,G7)>1,TRUE,FALSE),IF(COUNTIF(F7:I7,H7)>1,TRUE,FALSE),IF(COUNTIF(F7:I7,I7)>1,TRUE,FALSE)) -> TRUE | O7: =AND(N7=TRUE, COUNTIF(F7:I7, "100")) -> FALSE | P7: {=IFS(K7=TRUE, Q7, L7=TRUE, Q7, N7=FALSE, Q7, F7=G7, Q7, F7=Q7, Q7)} -> 1 | Q7: =MODE(F7:I7) -> 1
A8: 6 | B8: Alt Prime Rd. 1 | C8: 1 | D8: 20220505mouse1_OD_R_4_0_0000009_Structure_0002D1 | E8: https://drive.google.com/file/d/1mtU3TLB5IODf-xBWLZ_mPu35HQvsjrlb/view?usp=drive_link | F8: 1 | G8: 1 | H8: 1 | J8: =COUNTA(F8:I8) -> 3 | K8: {=IFS(OR(F8="",G8="",H8="",I8=""), FALSE, OR(F8<>G8, F8<>H8, F8<>I8, G8<>H8, G8<>I8, H8<>I8), FALSE, OR(F8=G8, F8=H8, F8=I8, G8=H8,G8=I8, H8=I8), TRUE)} -> FALSE | L8: =OR(AND(F8=G8,G8=H8),AND(H8=I8,F8=I8),AND(G8=H8,H8=I8), AND(F8=G8,G8=I8)) -> TRUE | M8: =OR(F8=G8,G8=H8,H8=I8,F8=I8, G8=I8, F8=H8) -> TRUE | N8: =AND(K8=FALSE,L8=FALSE,IF(COUNTIF(F8:I8,F8)>1,TRUE,FALSE),IF(COUNTIF(F8:I8,G8)>1,TRUE,FALSE),IF(COUNTIF(F8:I8,H8)>1,TRUE,FALSE),IF(COUNTIF(F8:I8,I8)>1,TRUE,FALSE)) -> FALSE | O8: =AND(N8=TRUE, COUNTIF(F8:I8, "100")) -> FALSE | P8: {=IFS(K8=TRUE, Q8, L8=TRUE, Q8, N8=FALSE, Q8, F8=G8, Q8, F8=Q8, Q8)} -> 1 | Q8: =MODE(F8:I8) -> 1
A9: 7 | B9: Alt Prime Rd. 1 | C9: 1 | D9: 20220505mouse1_OD_R_4_0_0000009_Structure_0003D1 | E9: https://drive.google.com/file/d/1w_pQSRD31zRuvz49ekXdmLEfLlikcpf5/view?usp=sharing | F9: 2 | G9: 2 | H9: 1 | I9: 2 | J9: =COUNTA(F9:I9) -> 4 | K9: {=IFS(OR(F9="",G9="",H9="",I9=""), FALSE, OR(F9<>G9, F9<>H9, F9<>I9, G9<>H9, G9<>I9, H9<>I9), FALSE, OR(F9=G9, F9=H9, F9=I9, G9=H9,G9=I9, H9=I9), TRUE)} -> FALSE | L9: =OR(AND(F9=G9,G9=H9),AND(H9=I9,F9=I9),AND(G9=H9,H9=I9), AND(F9=G9,G9=I9)) -> TRUE | M9: =OR(F9=G9,G9=H9,H9=I9,F9=I9, G9=I9, F9=H9) -> TRUE | N9: =AND(K9=FALSE,L9=FALSE,IF(COUNTIF(F9:I9,F9)>1,TRUE,FALSE),IF(COUNTIF(F9:I9,G9)>1,TRUE,FALSE),IF(COUNTIF(F9:I9,H9)>1,TRUE,FALSE),IF(COUNTIF(F9:I9,I9)>1,TRUE,FALSE)) -> FALSE | O9: =AND(N9=TRUE, COUNTIF(F9:I9, "100")) -> FALSE | P9: {=IFS(K9=TRUE, Q9, L9=TRUE, Q9, N9=FALSE, Q9, F9=G9, Q9, F9=Q9, Q9)} -> 2 | Q9: =MODE(F9:I9) -> 2
A10: 8 | B10: Alt Prime Rd. 1 | C10: 1 | D10: 20220505mouse1_OD_R_4_0_0000009_Structure_0004D1 | E10: https://drive.google.com/file/d/1MDZSz-goWbY9afJAjOb3JEZkQHdHt6qy/view?usp=drive_link | F10: 2 | G10: 2 | H10: 0.5 | J10: =COUNTA(F10:I10) -> 3 | K10: {=IFS(OR(F10="",G10="",H10="",I10=""), FALSE, OR(F10<>G10, F10<>H10, F10<>I10, G10<>H10, G10<>I10, H10<>I10), FALSE, OR(F10=G10, F10=H10, F10=I10, G10=H10,G10=I10, H10=I10), TRUE)} -> FALSE | L10: =OR(AND(F10=G10,G10=H10),AND(H10=I10,F10=I10),AND(G10=H10,H10=I10), AND(F10=G10,G10=I10)) -> FALSE | M10: =OR(F10=G10,G10=H10,H10=I10,F10=I10, G10=I10, F10=H10) -> TRUE | N10: =AND(K10=FALSE,L10=FALSE,IF(COUNTIF(F10:I10,F10)>1,TRUE,FALSE),IF(COUNTIF(F10:I10,G10)>1,TRUE,FALSE),IF(COUNTIF(F10:I10,H10)>1,TRUE,FALSE),IF(COUNTIF(F10:I10,I10)>1,TRUE,FALSE)) -> FALSE | O10: =AND(N10=TRUE, COUNTIF(F10:I10, "100")) -> FALSE | P10: {=IFS(K10=TRUE, Q10, L10=TRUE, Q10, N10=FALSE, Q10, F10=G10, Q10, F10=Q10, Q10)} -> 2 | Q10: =MODE(F10:I10) -> 2
A11: 9 | B11: Alt Prime Rd. 1 | C11: 1 | D11: 20220505mouse2_OD_R_2_0_0000009_Structure_0001 | E11: https://drive.google.com/file/d/1_6p84kHnBbg8dqBRDHkadbBYQlexQBqf/view?usp=sharing | F11: 2 | G11: 2 | H11: 3 | I11: 2 | J11: =COUNTA(F11:I11) -> 4 | K11: {=IFS(OR(F11="",G11="",H11="",I11=""), FALSE, OR(F11<>G11, F11<>H11, F11<>I11, G11<>H11, G11<>I11, H11<>I11), FALSE, OR(F11=G11, F11=H11, F11=I11, G11=H11,G11=I11, H11=I11), TRUE)} -> FALSE | L11: =OR(AND(F11=G11,G11=H11),AND(H11=I11,F11=I11),AND(G11=H11,H11=I11), AND(F11=G11,G11=I11)) -> TRUE | M11: =OR(F11=G11,G11=H11,H11=I11,F11=I11, G11=I11, F11=H11) -> TRUE | N11: =AND(K11=FALSE,L11=FALSE,IF(COUNTIF(F11:I11,F11)>1,TRUE,FALSE),IF(COUNTIF(F11:I11,G11)>1,TRUE,FALSE),IF(COUNTIF(F11:I11,H11)>1,TRUE,FALSE),IF(COUNTIF(F11:I11,I11)>1,TRUE,FALSE)) -> FALSE | O11: =AND(N11=TRUE, COUNTIF(F11:I11, "100")) -> FALSE | P11: {=IFS(K11=TRUE, Q11, L11=TRUE, Q11, N11=FALSE, Q11, F11=G11, Q11, F11=Q11, Q11)} -> 2 | Q11: =MODE(F11:I11) -> 2
A12: 10 | B12: Alt Prime Rd. 1 | C12: 1 | D12: 20220505mouse2_OD_R_2_0_0000009_Structure_0002 | E12: https://drive.google.com/file/d/1r0qbYe1s1sX2BP6kMRo3wQGGt8SldcpJ/view?usp=drive_link | F12: 1 | H12: 2 | I12: 2 | J12: =COUNTA(F12:I12) -> 3 | K12: {=IFS(OR(F12="",G12="",H12="",I12=""), FALSE, OR(F12<>G12, F12<>H12, F12<>I12, G12<>H12, G12<>I12, H12<>I12), FALSE, OR(F12=G12, F12=H12, F12=I12, G12=H12,G12=I12, H12=I12), TRUE)} -> FALSE | L12: =OR(AND(F12=G12,G12=H12),AND(H12=I12,F12=I12),AND(G12=H12,H12=I12), AND(F12=G12,G12=I12)) -> FALSE | M12: =OR(F12=G12,G12=H12,H12=I12,F12=I12, G12=I12, F12=H12) -> TRUE | N12: =AND(K12=FALSE,L12=FALSE,IF(COUNTIF(F12:I12,F12)>1,TRUE,FALSE),IF(COUNTIF(F12:I12,G12)>1,TRUE,FALSE),IF(COUNTIF(F12:I12,H12)>1,TRUE,FALSE),IF(COUNTIF(F12:I12,I12)>1,TRUE,FALSE)) -> FALSE | O12: =AND(N12=TRUE, COUNTIF(F12:I12, "100")) -> FALSE | P12: {=IFS(K12=TRUE, Q12, L12=TRUE, Q12, N12=FALSE, Q12, F12=G12, Q12, F12=Q12, Q12)} -> 2 | Q12: =MODE(F12:I12) -> 2
A13: 11 | B13: Alt Prime Rd. 1 | C13: 1 | D13: 20220505mouse2_OD_R_2_0_0000009_Structure_0003 | E13: https://drive.google.com/file/d/1OWwwytHPsVPefD4v4iH9zfFsDETkq9gI/view?usp=sharing | F13: 1 | G13: 2 | H13: 2 | I13: 2 | J13: =COUNTA(F13:I13) -> 4 | K13: {=IFS(OR(F13="",G13="",H13="",I13=""), FALSE, OR(F13<>G13, F13<>H13, F13<>I13, G13<>H13, G13<>I13, H13<>I13), FALSE, OR(F13=G13, F13=H13, F13=I13, G13=H13,G13=I13, H13=I13), TRUE)} -> FALSE | L13: =OR(AND(F13=G13,G13=H13),AND(H13=I13,F13=I13),AND(G13=H13,H13=I13), AND(F13=G13,G13=I13)) -> TRUE | M13: =OR(F13=G13,G13=H13,H13=I13,F13=I13, G13=I13, F13=H13) -> TRUE | N13: =AND(K13=FALSE,L13=FALSE,IF(COUNTIF(F13:I13,F13)>1,TRUE,FALSE),IF(COUNTIF(F13:I13,G13)>1,TRUE,FALSE),IF(COUNTIF(F13:I13,H13)>1,TRUE,FALSE),IF(COUNTIF(F13:I13,I13)>1,TRUE,FALSE)) -> FALSE | O13: =AND(N13=TRUE, COUNTIF(F13:I13, "100")) -> FALSE | P13: {=IFS(K13=TRUE, Q13, L13=TRUE, Q13, N13=FALSE, Q13, F13=G13, Q13, F13=Q13, Q13)} -> 2 | Q13: =MODE(F13:I13) -> 2
A14: 12 | B14: Alt Prime Rd. 1 | C14: 1 | D14: 20220505mouse2_OD_R_2_0_0000009_Structure_0004 | E14: https://drive.google.com/file/d/1VS4YBP8KdMlY0qj8HFn4Xna0xnQI0R3y/view?usp=drive_link | F14: 1 | H14: 2 | I14: 2 | J14: =COUNTA(F14:I14) -> 3 | K14: {=IFS(OR(F14="",G14="",H14="",I14=""), FALSE, OR(F14<>G14, F14<>H14, F14<>I14, G14<>H14, G14<>I14, H14<>I14), FALSE, OR(F14=G14, F14=H14, F14=I14, G14=H14,G14=I14, H14=I14), TRUE)} -> FALSE | L14: =OR(AND(F14=G14,G14=H14),AND(H14=I14,F14=I14),AND(G14=H14,H14=I14), AND(F14=G14,G14=I14)) -> FALSE | M14: =OR(F14=G14,G14=H14,H14=I14,F14=I14, G14=I14, F14=H14) -> TRUE | N14: =AND(K14=FALSE,L14=FALSE,IF(COUNTIF(F14:I14,F14)>1,TRUE,FALSE),IF(COUNTIF(F14:I14,G14)>1,TRUE,FALSE),IF(COUNTIF(F14:I14,H14)>1,TRUE,FALSE),IF(COUNTIF(F14:I14,I14)>1,TRUE,FALSE)) -> FALSE | O14: =AND(N14=TRUE, COUNTIF(F14:I14, "100")) -> FALSE | P14: {=IFS(K14=TRUE, Q14, L14=TRUE, Q14, N14=FALSE, Q14, F14=G14, Q14, F14=Q14, Q14)} -> 2 | Q14: =MODE(F14:I14) -> 2
A15: 13 | B15: Alt Prime Rd. 1 | C15: 1 | D15: 20220505mouse2_OD_R_4_0_0000002_Structure_0001 | E15: https://drive.google.com/file/d/1yZKIFNu1jW6bE0G39dtjcNpMuRffYG1A/view?usp=sharing | F15: 0.5 | G15: 0 | H15: 0.5 | I15: 0.5 | J15: =COUNTA(F15:I15) -> 4 | K15: {=IFS(OR(F15="",G15="",H15="",I15=""), FALSE, OR(F15<>G15, F15<>H15, F15<>I15, G15<>H15, G15<>I15, H15<>I15), FALSE, OR(F15=G15, F15=H15, F15=I15, G15=H15,G15=I15, H15=I15), TRUE)} -> FALSE | L15: =OR(AND(F15=G15,G15=H15),AND(H15=I15,F15=I15),AND(G15=H15,H15=I15), AND(F15=G15,G15=I15)) -> TRUE | M15: =OR(F15=G15,G15=H15,H15=I15,F15=I15, G15=I15, F15=H15) -> TRUE | N15: =AND(K15=FALSE,L15=FALSE,IF(COUNTIF(F15:I15,F15)>1,TRUE,FALSE),IF(COUNTIF(F15:I15,G15)>1,TRUE,FALSE),IF(COUNTIF(F15:I15,H15)>1,TRUE,FALSE),IF(COUNTIF(F15:I15,I15)>1,TRUE,FALSE)) -> FALSE | O15: =AND(N15=TRUE, COUNTIF(F15:I15, "100")) -> FALSE | P15: {=IFS(K15=TRUE, Q15, L15=TRUE, Q15, N15=FALSE, Q15, F15=G15, Q15, F15=Q15, Q15)} -> 0.5 | Q15: =MODE(F15:I15) -> 0.5
A16: 14 | B16: Alt Prime Rd. 1 | C16: 1 | D16: 20220505mouse2_OD_R_4_0_0000002_Structure_0002 | E16: https://drive.google.com/file/d/1xpltJOeFc5d-wI86cZFAHn4_XqTl2tdK/view?usp=drive_link | F16: 1 | G16: 1 | H16: 1 | J16: =COUNTA(F16:I16) -> 3 | K16: {=IFS(OR(F16="",G16="",H16="",I16=""), FALSE, OR(F16<>G16, F16<>H16, F16<>I16, G16<>H16, G16<>I16, H16<>I16), FALSE, OR(F16=G16, F16=H16, F16=I16, G16=H16,G16=I16, H16=I16), TRUE)} -> FALSE | L16: =OR(AND(F16=G16,G16=H16),AND(H16=I16,F16=I16),AND(G16=H16,H16=I16), AND(F16=G16,G16=I16)) -> TRUE | M16: =OR(F16=G16,G16=H16,H16=I16,F16=I16, G16=I16, F16=H16) -> TRUE | N16: =AND(K16=FALSE,L16=FALSE,IF(COUNTIF(F16:I16,F16)>1,TRUE,FALSE),IF(COUNTIF(F16:I16,G16)>1,TRUE,FALSE),IF(COUNTIF(F16:I16,H16)>1,TRUE,FALSE),IF(COUNTIF(F16:I16,I16)>1,TRUE,FALSE)) -> FALSE | O16: =AND(N16=TRUE, COUNTIF(F16:I16, "100")) -> FALSE | P16: {=IFS(K16=TRUE, Q16, L16=TRUE, Q16, N16=FALSE, Q16, F16=G16, Q16, F16=Q16, Q16)} -> 1 | Q16: =MODE(F16:I16) -> 1
A17: 15 | B17: Alt Prime Rd. 1 | C17: 1 | D17: 20220505mouse2_OD_R_4_0_0000002_Structure_0003 | E17: https://drive.google.com/file/d/1zdeadoelUN17JRsqFP3WcgzPbPA-AOnJ/view?usp=sharing | F17: 1 | G17: 1 | H17: 1 | I17: 1 | J17: =COUNTA(F17:I17) -> 4 | K17: {=IFS(OR(F17="",G17="",H17="",I17=""), FALSE, OR(F17<>G17, F17<>H17, F17<>I17, G17<>H17, G17<>I17, H17<>I17), FALSE, OR(F17=G17, F17=H17, F17=I17, G17=H17,G17=I17, H17=I17), TRUE)} -> TRUE | L17: =OR(AND(F17=G17,G17=H17),AND(H17=I17,F17=I17),AND(G17=H17,H17=I17), AND(F17=G17,G17=I17)) -> TRUE | M17: =OR(F17=G17,G17=H17,H17=I17,F17=I17, G17=I17, F17=H17) -> TRUE | N17: =AND(K17=FALSE,L17=FALSE,IF(COUNTIF(F17:I17,F17)>1,TRUE,FALSE),IF(COUNTIF(F17:I17,G17)>1,TRUE,FALSE),IF(COUNTIF(F17:I17,H17)>1,TRUE,FALSE),IF(COUNTIF(F17:I17,I17)>1,TRUE,FALSE)) -> FALSE | O17: =AND(N17=TRUE, COUNTIF(F17:I17, "100")) -> FALSE | P17: {=IFS(K17=TRUE, Q17, L17=TRUE, Q17, N17=FALSE, Q17, F17=G17, Q17, F17=Q17, Q17)} -> 1 | Q17: =MODE(F17:I17) -> 1
A18: 16 | B18: Alt Prime Rd. 1 | C18: 1 | D18: 20220505mouse2_OD_R_4_0_0000002_Structure_0004 | E18: https://drive.google.com/file/d/1SKyPcx3GJzBANF7XPkkzidkibfsCks1W/view?usp=drive_link | F18: 1 | H18: 1 | I18: 2 | J18: =COUNTA(F18:I18) -> 3 | K18: {=IFS(OR(F18="",G18="",H18="",I18=""), FALSE, OR(F18<>G18, F18<>H18, F18<>I18, G18<>H18, G18<>I18, H18<>I18), FALSE, OR(F18=G18, F18=H18, F18=I18, G18=H18,G18=I18, H18=I18), TRUE)} -> FALSE | L18: =OR(AND(F18=G18,G18=H18),AND(H18=I18,F18=I18),AND(G18=H18,H18=I18), AND(F18=G18,G18=I18)) -> FALSE | M18: =OR(F18=G18,G18=H18,H18=I18,F18=I18, G18=I18, F18=H18) -> TRUE | N18: =AND(K18=FALSE,L18=FALSE,IF(COUNTIF(F18:I18,F18)>1,TRUE,FALSE),IF(COUNTIF(F18:I18,G18)>1,TRUE,FALSE),IF(COUNTIF(F18:I18,H18)>1,TRUE,FALSE),IF(COUNTIF(F18:I18,I18)>1,TRUE,FALSE)) -> FALSE | O18: =AND(N18=TRUE, COUNTIF(F18:I18, "100")) -> FALSE | P18: {=IFS(K18=TRUE, Q18, L18=TRUE, Q18, N18=FALSE, Q18, F18=G18, Q18, F18=Q18, Q18)} -> 1 | Q18: =MODE(F18:I18) -> 1
A19: 17 | B19: Alt Prime Rd. 1 | C19: 1 | D19: 20220505mouse3_OD_R_2_0_0000002_Structure_0001 | E19: https://drive.google.com/file/d/1xTQrAM-b-r4NccJ0sNKKjPfbl3oSPM-N/view?usp=sharing | F19: 2 | G19: 2 | H19: 1 | I19: 2 | J19: =COUNTA(F19:I19) -> 4 | K19: {=IFS(OR(F19="",G19="",H19="",I19=""), FALSE, OR(F19<>G19, F19<>H19, F19<>I19, G19<>H19, G19<>I19, H19<>I19), FALSE, OR(F19=G19, F19=H19, F19=I19, G19=H19,G19=I19, H19=I19), TRUE)} -> FALSE | L19: =OR(AND(F19=G19,G19=H19),AND(H19=I19,F19=I19),AND(G19=H19,H19=I19), AND(F19=G19,G19=I19)) -> TRUE | M19: =OR(F19=G19,G19=H19,H19=I19,F19=I19, G19=I19, F19=H19) -> TRUE | N19: =AND(K19=FALSE,L19=FALSE,IF(COUNTIF(F19:I19,F19)>1,TRUE,FALSE),IF(COUNTIF(F19:I19,G19)>1,TRUE,FALSE),IF(COUNTIF(F19:I19,H19)>1,TRUE,FALSE),IF(COUNTIF(F19:I19,I19)>1,TRUE,FALSE)) -> FALSE | O19: =AND(N19=TRUE, COUNTIF(F19:I19, "100")) -> FALSE | P19: {=IFS(K19=TRUE, Q19, L19=TRUE, Q19, N19=FALSE, Q19, F19=G19, Q19, F19=Q19, Q19)} -> 2 | Q19: =MODE(F19:I19) -> 2
A20: 18 | B20: Alt Prime Rd. 1 | C20: 1 | D20: 20220505mouse3_OD_R_2_0_0000002_Structure_0002 | E20: https://drive.google.com/file/d/1PiFtlbmr6yUVjL6qOP18Kmi6ce-Z_z4Y/view?usp=drive_link | F20: 4 | H20: 3 | I20: 3 | J20: =COUNTA(F20:I20) -> 3 | K20: {=IFS(OR(F20="",G20="",H20="",I20=""), FALSE, OR(F20<>G20, F20<>H20, F20<>I20, G20<>H20, G20<>I20, H20<>I20), FALSE, OR(F20=G20, F20=H20, F20=I20, G20=H20,G20=I20, H20=I20), TRUE)} -> FALSE | L20: =OR(AND(F20=G20,G20=H20),AND(H20=I20,F20=I20),AND(G20=H20,H20=I20), AND(F20=G20,G20=I20)) -> FALSE | M20: =OR(F20=G20,G20=H20,H20=I20,F20=I20, G20=I20, F20=H20) -> TRUE | N20: =AND(K20=FALSE,L20=FALSE,IF(COUNTIF(F20:I20,F20)>1,TRUE,FALSE),IF(COUNTIF(F20:I20,G20)>1,TRUE,FALSE),IF(COUNTIF(F20:I20,H20)>1,TRUE,FALSE),IF(COUNTIF(F20:I20,I20)>1,TRUE,FALSE)) -> FALSE | O20: =AND(N20=TRUE, COUNTIF(F20:I20, "100")) -> FALSE | P20: {=IFS(K20=TRUE, Q20, L20=TRUE, Q20, N20=FALSE, Q20, F20=G20, Q20, F20=Q20, Q20)} -> 3 | Q20: =MODE(F20:I20) -> 3
A21: 19 | B21: Alt Prime Rd. 1 | C21: 1 | D21: 20220505mouse3_OD_R_2_0_0000002_Structure_0003 | E21: https://drive.google.com/file/d/1iXrzQfODwMyqlmgL_I7lga8mbWs9L_d0/view?usp=sharing | F21: 2 | G21: 2 | H21: 1 | I21: 2 | J21: =COUNTA(F21:I21) -> 4 | K21: {=IFS(OR(F21="",G21="",H21="",I21=""), FALSE, OR(F21<>G21, F21<>H21, F21<>I21, G21<>H21, G21<>I21, H21<>I21), FALSE, OR(F21=G21, F21=H21, F21=I21, G21=H21,G21=I21, H21=I21), TRUE)} -> FALSE | L21: =OR(AND(F21=G21,G21=H21),AND(H21=I21,F21=I21),AND(G21=H21,H21=I21), AND(F21=G21,G21=I21)) -> TRUE | M21: =OR(F21=G21,G21=H21,H21=I21,F21=I21, G21=I21, F21=H21) -> TRUE | N21: =AND(K21=FALSE,L21=FALSE,IF(COUNTIF(F21:I21,F21)>1,TRUE,FALSE),IF(COUNTIF(F21:I21,G21)>1,TRUE,FALSE),IF(COUNTIF(F21:I21,H21)>1,TRUE,FALSE),IF(COUNTIF(F21:I21,I21)>1,TRUE,FALSE)) -> FALSE | O21: =AND(N21=TRUE, COUNTIF(F21:I21, "100")) -> FALSE | P21: {=IFS(K21=TRUE, Q21, L21=TRUE, Q21, N21=FALSE, Q21, F21=G21, Q21, F21=Q21, Q21)} -> 2 | Q21: =MODE(F21:I21) -> 2
A22: 20 | B22: Alt Prime Rd. 1 | C22: 1 | D22: 20220505mouse3_OD_R_2_0_0000002_Structure_0004 | E22: https://drive.google.com/file/d/1-SUEa-DZB3j8dbqdMaKucMKllGFa1EJD/view?usp=drive_link | F22: 3 | H22: 2 | I22: 3 | J22: =COUNTA(F22:I22) -> 3 | K22: {=IFS(OR(F22="",G22="",H22="",I22=""), FALSE, OR(F22<>G22, F22<>H22, F22<>I22, G22<>H22, G22<>I22, H22<>I22), FALSE, OR(F22=G22, F22=H22, F22=I22, G22=H22,G22=I22, H22=I22), TRUE)} -> FALSE | L22: =OR(AND(F22=G22,G22=H22),AND(H22=I22,F22=I22),AND(G22=H22,H22=I22), AND(F22=G22,G22=I22)) -> FALSE | M22: =OR(F22=G22,G22=H22,H22=I22,F22=I22, G22=I22, F22=H22) -> TRUE | N22: =AND(K22=FALSE,L22=FALSE,IF(COUNTIF(F22:I22,F22)>1,TRUE,FALSE),IF(COUNTIF(F22:I22,G22)>1,TRUE,FALSE),IF(COUNTIF(F22:I22,H22)>1,TRUE,FALSE),IF(COUNTIF(F22:I22,I22)>1,TRUE,FALSE)) -> FALSE | O22: =AND(N22=TRUE, COUNTIF(F22:I22, "100")) -> FALSE | P22: {=IFS(K22=TRUE, Q22, L22=TRUE, Q22, N22=FALSE, Q22, F22=G22, Q22, F22=Q22, Q22)} -> 3 | Q22: =MODE(F22:I22) -> 3
A23: 21 | B23: Alt Prime Rd. 1 | C23: 1 | D23: 20220505mouse3_OD_R_4_0_0000009_Structure_0001 | E23: https://drive.google.com/file/d/17qjPgEcJ5e3gy5gPhmQej30X-msf63_a/view?usp=sharing | F23: 2 | G23: 2 | H23: 2 | I23: 2 | J23: =COUNTA(F23:I23) -> 4 | K23: {=IFS(OR(F23="",G23="",H23="",I23=""), FALSE, OR(F23<>G23, F23<>H23, F23<>I23, G23<>H23, G23<>I23, H23<>I23), FALSE, OR(F23=G23, F23=H23, F23=I23, G23=H23,G23=I23, H23=I23), TRUE)} -> TRUE | L23: =OR(AND(F23=G23,G23=H23),AND(H23=I23,F23=I23),AND(G23=H23,H23=I23), AND(F23=G23,G23=I23)) -> TRUE | M23: =OR(F23=G23,G23=H23,H23=I23,F23=I23, G23=I23, F23=H23) -> TRUE | N23: =AND(K23=FALSE,L23=FALSE,IF(COUNTIF(F23:I23,F23)>1,TRUE,FALSE),IF(COUNTIF(F23:I23,G23)>1,TRUE,FALSE),IF(COUNTIF(F23:I23,H23)>1,TRUE,FALSE),IF(COUNTIF(F23:I23,I23)>1,TRUE,FALSE)) -> FALSE | O23: =AND(N23=TRUE, COUNTIF(F23:I23, "100")) -> FALSE | P23: {=IFS(K23=TRUE, Q23, L23=TRUE, Q23, N23=FALSE, Q23, F23=G23, Q23, F23=Q23, Q23)} -> 2 | Q23: =MODE(F23:I23) -> 2
A24: 22 | B24: Alt Prime Rd. 1 | C24: 1 | D24: 20220505mouse3_OD_R_4_0_0000009_Structure_0002 | E24: https://drive.google.com/file/d/16r-t7RfkxHRA8VcOgl6n525cAgbUh5x9/view?usp=drive_link | F24: 2 | H24: 2 | I24: 1 | J24: =COUNTA(F24:I24) -> 3 | K24: {=IFS(OR(F24="",G24="",H24="",I24=""), FALSE, OR(F24<>G24, F24<>H24, F24<>I24, G24<>H24, G24<>I24, H24<>I24), FALSE, OR(F24=G24, F24=H24, F24=I24, G24=H24,G24=I24, H24=I24), TRUE)} -> FALSE | L24: =OR(AND(F24=G24,G24=H24),AND(H24=I24,F24=I24),AND(G24=H24,H24=I24), AND(F24=G24,G24=I24)) -> FALSE | M24: =OR(F24=G24,G24=H24,H24=I24,F24=I24, G24=I24, F24=H24) -> TRUE | N24: =AND(K24=FALSE,L24=FALSE,IF(COUNTIF(F24:I24,F24)>1,TRUE,FALSE),IF(COUNTIF(F24:I24,G24)>1,TRUE,FALSE),IF(COUNTIF(F24:I24,H24)>1,TRUE,FALSE),IF(COUNTIF(F24:I24,I24)>1,TRUE,FALSE)) -> FALSE | O24: =AND(N24=TRUE, COUNTIF(F24:I24, "100")) -> FALSE | P24: {=IFS(K24=TRUE, Q24, L24=TRUE, Q24, N24=FALSE, Q24, F24=G24, Q24, F24=Q24, Q24)} -> 2 | Q24: =MODE(F24:I24) -> 2
A25: 23 | B25: Alt Prime Rd. 1 | C25: 1 | D25: 20220505mouse3_OD_R_4_0_0000009_Structure_0003 | E25: https://drive.google.com/file/d/1raAMPnEV5Y5010X9vXV1zrJsjTsJ3gqZ/view?usp=sharing | F25: 2 | G25: 2 | H25: 2 | I25: 2 | J25: =COUNTA(F25:I25) -> 4 | K25: {=IFS(OR(F25="",G25="",H25="",I25=""), FALSE, OR(F25<>G25, F25<>H25, F25<>I25, G25<>H25, G25<>I25, H25<>I25), FALSE, OR(F25=G25, F25=H25, F25=I25, G25=H25,G25=I25, H25=I25), TRUE)} -> TRUE | L25: =OR(AND(F25=G25,G25=H25),AND(H25=I25,F25=I25),AND(G25=H25,H25=I25), AND(F25=G25,G25=I25)) -> TRUE | M25: =OR(F25=G25,G25=H25,H25=I25,F25=I25, G25=I25, F25=H25) -> TRUE | N25: =AND(K25=FALSE,L25=FALSE,IF(COUNTIF(F25:I25,F25)>1,TRUE,FALSE),IF(COUNTIF(F25:I25,G25)>1,TRUE,FALSE),IF(COUNTIF(F25:I25,H25)>1,TRUE,FALSE),IF(COUNTIF(F25:I25,I25)>1,TRUE,FALSE)) -> FALSE | O25: =AND(N25=TRUE, COUNTIF(F25:I25, "100")) -> FALSE | P25: {=IFS(K25=TRUE, Q25, L25=TRUE, Q25, N25=FALSE, Q25, F25=G25, Q25, F25=Q25, Q25)} -> 2 | Q25: =MODE(F25:I25) -> 2
A26: 24 | B26: Alt Prime Rd. 1 | C26: 1 | D26: 20220505mouse3_OD_R_4_0_0000009_Structure_0004 | E26: https://drive.google.com/file/d/1gGaGeMaALafEadsBB7ASw3nJMeqYyuZg/view?usp=drive_link | F26: 2 | G26: 2 | H26: 0.5 | J26: =COUNTA(F26:I26) -> 3 | K26: {=IFS(OR(F26="",G26="",H26="",I26=""), FALSE, OR(F26<>G26, F26<>H26, F26<>I26, G26<>H26, G26<>I26, H26<>I26), FALSE, OR(F26=G26, F26=H26, F26=I26, G26=H26,G26=I26, H26=I26), TRUE)} -> FALSE | L26: =OR(AND(F26=G26,G26=H26),AND(H26=I26,F26=I26),AND(G26=H26,H26=I26), AND(F26=G26,G26=I26)) -> FALSE | M26: =OR(F26=G26,G26=H26,H26=I26,F26=I26, G26=I26, F26=H26) -> TRUE | N26: =AND(K26=FALSE,L26=FALSE,IF(COUNTIF(F26:I26,F26)>1,TRUE,FALSE),IF(COUNTIF(F26:I26,G26)>1,TRUE,FALSE),IF(COUNTIF(F26:I26,H26)>1,TRUE,FALSE),IF(COUNTIF(F26:I26,I26)>1,TRUE,FALSE)) -> FALSE | O26: =AND(N26=TRUE, COUNTIF(F26:I26, "100")) -> FALSE | P26: {=IFS(K26=TRUE, Q26, L26=TRUE, Q26, N26=FALSE, Q26, F26=G26, Q26, F26=Q26, Q26)} -> 2 | Q26: =MODE(F26:I26) -> 2
A27: 25 | B27: Alt Prime Rd. 1 | C27: 1 | D27: 20220505mouse4_OD_R_2_0_0000009_Structure_0001 | E27: https://drive.google.com/file/d/1P56qzOyJXvtnb-RIhmIHnmCYf8yZdgyQ/view?usp=sharing | F27: 0.5 | G27: 0.5 | H27: 0.5 | I27: 0.5 | J27: =COUNTA(F27:I27) -> 4 | K27: {=IFS(OR(F27="",G27="",H27="",I27=""), FALSE, OR(F27<>G27, F27<>H27, F27<>I27, G27<>H27, G27<>I27, H27<>I27), FALSE, OR(F27=G27, F27=H27, F27=I27, G27=H27,G27=I27, H27=I27), TRUE)} -> TRUE | L27: =OR(AND(F27=G27,G27=H27),AND(H27=I27,F27=I27),AND(G27=H27,H27=I27), AND(F27=G27,G27=I27)) -> TRUE | M27: =OR(F27=G27,G27=H27,H27=I27,F27=I27, G27=I27, F27=H27) -> TRUE | N27: =AND(K27=FALSE,L27=FALSE,IF(COUNTIF(F27:I27,F27)>1,TRUE,FALSE),IF(COUNTIF(F27:I27,G27)>1,TRUE,FALSE),IF(COUNTIF(F27:I27,H27)>1,TRUE,FALSE),IF(COUNTIF(F27:I27,I27)>1,TRUE,FALSE)) -> FALSE | O27: =AND(N27=TRUE, COUNTIF(F27:I27, "100")) -> FALSE | P27: {=IFS(K27=TRUE, Q27, L27=TRUE, Q27, N27=FALSE, Q27, F27=G27, Q27, F27=Q27, Q27)} -> 0.5 | Q27: =MODE(F27:I27) -> 0.5
A28: 26 | B28: Alt Prime Rd. 1 | C28: 1 | D28: 20220505mouse4_OD_R_2_0_0000009_Structure_0002 | E28: https://drive.google.com/file/d/1MJBCK8iS0Iyqsfg7oiI3yAEkwlGHARur/view?usp=drive_link | F28: 0.5 | H28: 0.5 | I28: 1 | J28: =COUNTA(F28:I28) -> 3 | K28: {=IFS(OR(F28="",G28="",H28="",I28=""), FALSE, OR(F28<>G28, F28<>H28, F28<>I28, G28<>H28, G28<>I28, H28<>I28), FALSE, OR(F28=G28, F28=H28, F28=I28, G28=H28,G28=I28, H28=I28), TRUE)} -> FALSE | L28: =OR(AND(F28=G28,G28=H28),AND(H28=I28,F28=I28),AND(G28=H28,H28=I28), AND(F28=G28,G28=I28)) -> FALSE | M28: =OR(F28=G28,G28=H28,H28=I28,F28=I28, G28=I28, F28=H28) -> TRUE | N28: =AND(K28=FALSE,L28=FALSE,IF(COUNTIF(F28:I28,F28)>1,TRUE,FALSE),IF(COUNTIF(F28:I28,G28)>1,TRUE,FALSE),IF(COUNTIF(F28:I28,H28)>1,TRUE,FALSE),IF(COUNTIF(F28:I28,I28)>1,TRUE,FALSE)) -> FALSE | O28: =AND(N28=TRUE, COUNTIF(F28:I28, "100")) -> FALSE | P28: {=IFS(K28=TRUE, Q28, L28=TRUE, Q28, N28=FALSE, Q28, F28=G28, Q28, F28=Q28, Q28)} -> 0.5 | Q28: =MODE(F28:I28) -> 0.5
A29: 27 | B29: Alt Prime Rd. 1 | C29: 1 | D29: 20220505mouse4_OD_R_2_0_0000009_Structure_0003 | E29: https://drive.google.com/file/d/1cONLD-kqJLlZw_tp_yMt6hcis2lPilO3/view?usp=sharing | F29: 0.5 | G29: 1 | H29: 0.5 | I29: 0.5 | J29: =COUNTA(F29:I29) -> 4 | K29: {=IFS(OR(F29="",G29="",H29="",I29=""), FALSE, OR(F29<>G29, F29<>H29, F29<>I29, G29<>H29, G29<>I29, H29<>I29), FALSE, OR(F29=G29, F29=H29, F29=I29, G29=H29,G29=I29, H29=I29), TRUE)} -> FALSE | L29: =OR(AND(F29=G29,G29=H29),AND(H29=I29,F29=I29),AND(G29=H29,H29=I29), AND(F29=G29,G29=I29)) -> TRUE | M29: =OR(F29=G29,G29=H29,H29=I29,F29=I29, G29=I29, F29=H29) -> TRUE | N29: =AND(K29=FALSE,L29=FALSE,IF(COUNTIF(F29:I29,F29)>1,TRUE,FALSE),IF(COUNTIF(F29:I29,G29)>1,TRUE,FALSE),IF(COUNTIF(F29:I29,H29)>1,TRUE,FALSE),IF(COUNTIF(F29:I29,I29)>1,TRUE,FALSE)) -> FALSE | O29: =AND(N29=TRUE, COUNTIF(F29:I29, "100")) -> FALSE | P29: {=IFS(K29=TRUE, Q29, L29=TRUE, Q29, N29=FALSE, Q29, F29=G29, Q29, F29=Q29, Q29)} -> 0.5 | Q29: =MODE(F29:I29) -> 0.5
A30: 28 | B30: Alt Prime Rd. 1 | C30: 1 | D30: 20220505mouse4_OD_R_2_0_0000009_Structure_0004 | E30: https://drive.google.com/file/d/1Dm2MybyuwzVyzW3gtJhbtwvsdPdwyEO8/view?usp=drive_link | F30: 0.5 | G30: 0.5 | H30: 0.5 | J30: =COUNTA(F30:I30) -> 3 | K30: {=IFS(OR(F30="",G30="",H30="",I30=""), FALSE, OR(F30<>G30, F30<>H30, F30<>I30, G30<>H30, G30<>I30, H30<>I30), FALSE, OR(F30=G30, F30=H30, F30=I30, G30=H30,G30=I30, H30=I30), TRUE)} -> FALSE | L30: =OR(AND(F30=G30,G30=H30),AND(H30=I30,F30=I30),AND(G30=H30,H30=I30), AND(F30=G30,G30=I30)) -> TRUE | M30: =OR(F30=G30,G30=H30,H30=I30,F30=I30, G30=I30, F30=H30) -> TRUE | N30: =AND(K30=FALSE,L30=FALSE,IF(COUNTIF(F30:I30,F30)>1,TRUE,FALSE),IF(COUNTIF(F30:I30,G30)>1,TRUE,FALSE),IF(COUNTIF(F30:I30,H30)>1,TRUE,FALSE),IF(COUNTIF(F30:I30,I30)>1,TRUE,FALSE)) -> FALSE | O30: =AND(N30=TRUE, COUNTIF(F30:I30, "100")) -> FALSE | P30: {=IFS(K30=TRUE, Q30, L30=TRUE, Q30, N30=FALSE, Q30, F30=G30, Q30, F30=Q30, Q30)} -> 0.5 | Q30: =MODE(F30:I30) -> 0.5
A31: 29 | B31: Alt Prime Rd. 1 | C31: 1 | D31: 20220505mouse4_OD_R_4_0_0000002_Structure_0001 | E31: https://drive.google.com/file/d/1NBa14fqiKm74YTxYugCidmiQblCmQSrn/view?usp=sharing | F31: 1 | G31: 1 | H31: 2 | I31: 1 | J31: =COUNTA(F31:I31) -> 4 | K31: {=IFS(OR(F31="",G31="",H31="",I31=""), FALSE, OR(F31<>G31, F31<>H31, F31<>I31, G31<>H31, G31<>I31, H31<>I31), FALSE, OR(F31=G31, F31=H31, F31=I31, G31=H31,G31=I31, H31=I31), TRUE)} -> FALSE | L31: =OR(AND(F31=G31,G31=H31),AND(H31=I31,F31=I31),AND(G31=H31,H31=I31), AND(F31=G31,G31=I31)) -> TRUE | M31: =OR(F31=G31,G31=H31,H31=I31,F31=I31, G31=I31, F31=H31) -> TRUE | N31: =AND(K31=FALSE,L31=FALSE,IF(COUNTIF(F31:I31,F31)>1,TRUE,FALSE),IF(COUNTIF(F31:I31,G31)>1,TRUE,FALSE),IF(COUNTIF(F31:I31,H31)>1,TRUE,FALSE),IF(COUNTIF(F31:I31,I31)>1,TRUE,FALSE)) -> FALSE | O31: =AND(N31=TRUE, COUNTIF(F31:I31, "100")) -> FALSE | P31: {=IFS(K31=TRUE, Q31, L31=TRUE, Q31, N31=FALSE, Q31, F31=G31, Q31, F31=Q31, Q31)} -> 1 | Q31: =MODE(F31:I31) -> 1
A32: 30 | B32: Alt Prime Rd. 1 | C32: 1 | D32: 20220505mouse4_OD_R_4_0_0000002_Structure_0002 | E32: https://drive.google.com/file/d/1gs5T1vAiQ2wlBQaCRI0Bi-RUmZXTNKrf/view?usp=sharing | F32: 2 | H32: 2 | I32: 1 | J32: =COUNTA(F32:I32) -> 3 | K32: {=IFS(OR(F32="",G32="",H32="",I32=""), FALSE, OR(F32<>G32, F32<>H32, F32<>I32, G32<>H32, G32<>I32, H32<>I32), FALSE, OR(F32=G32, F32=H32, F32=I32, G32=H32,G32=I32, H32=I32), TRUE)} -> FALSE | L32: =OR(AND(F32=G32,G32=H32),AND(H32=I32,F32=I32),AND(G32=H32,H32=I32), AND(F32=G32,G32=I32)) -> FALSE | M32: =OR(F32=G32,G32=H32,H32=I32,F32=I32, G32=I32, F32=H32) -> TRUE | N32: =AND(K32=FALSE,L32=FALSE,IF(COUNTIF(F32:I32,F32)>1,TRUE,FALSE),IF(COUNTIF(F32:I32,G32)>1,TRUE,FALSE),IF(COUNTIF(F32:I32,H32)>1,TRUE,FALSE),IF(COUNTIF(F32:I32,I32)>1,TRUE,FALSE)) -> FALSE | O32: =AND(N32=TRUE, COUNTIF(F32:I32, "100")) -> FALSE | P32: {=IFS(K32=TRUE, Q32, L32=TRUE, Q32, N32=FALSE, Q32, F32=G32, Q32, F32=Q32, Q32)} -> 2 | Q32: =MODE(F32:I32) -> 2
A33: 31 | B33: Alt Prime Rd. 1 | C33: 1 | D33: 20220505mouse4_OD_R_4_0_0000002_Structure_0003 | E33: https://drive.google.com/file/d/1QZvxNDBSGquzVytQVLYHsWCX_yg3CBmH/view?usp=sharing | F33: 2 | G33: 2 | H33: 3 | I33: 2 | J33: =COUNTA(F33:I33) -> 4 | K33: {=IFS(OR(F33="",G33="",H33="",I33=""), FALSE, OR(F33<>G33, F33<>H33, F33<>I33, G33<>H33, G33<>I33, H33<>I33), FALSE, OR(F33=G33, F33=H33, F33=I33, G33=H33,G33=I33, H33=I33), TRUE)} -> FALSE | L33: =OR(AND(F33=G33,G33=H33),AND(H33=I33,F33=I33),AND(G33=H33,H33=I33), AND(F33=G33,G33=I33)) -> TRUE | M33: =OR(F33=G33,G33=H33,H33=I33,F33=I33, G33=I33, F33=H33) -> TRUE | N33: =AND(K33=FALSE,L33=FALSE,IF(COUNTIF(F33:I33,F33)>1,TRUE,FALSE),IF(COUNTIF(F33:I33,G33)>1,TRUE,FALSE),IF(COUNTIF(F33:I33,H33)>1,TRUE,FALSE),IF(COUNTIF(F33:I33,I33)>1,TRUE,FALSE)) -> FALSE | O33: =AND(N33=TRUE, COUNTIF(F33:I33, "100")) -> FALSE | P33: {=IFS(K33=TRUE, Q33, L33=TRUE, Q33, N33=FALSE, Q33, F33=G33, Q33, F33=Q33, Q33)} -> 2 | Q33: =MODE(F33:I33) -> 2
A34: 32 | B34: Alt Prime Rd. 1 | C34: 1 | D34: 20220505mouse4_OD_R_4_0_0000002_Structure_0004 | E34: https://drive.google.com/file/d/1PwXC271yZP_Gr5QLJgGjX7U8kFrvStMF/view?usp=sharing | F34: 2 | G34: 2 | H34: 2 | J34: =COUNTA(F34:I34) -> 3 | K34: {=IFS(OR(F34="",G34="",H34="",I34=""), FALSE, OR(F34<>G34, F34<>H34, F34<>I34, G34<>H34, G34<>I34, H34<>I34), FALSE, OR(F34=G34, F34=H34, F34=I34, G34=H34,G34=I34, H34=I34), TRUE)} -> FALSE | L34: =OR(AND(F34=G34,G34=H34),AND(H34=I34,F34=I34),AND(G34=H34,H34=I34), AND(F34=G34,G34=I34)) -> TRUE | M34: =OR(F34=G34,G34=H34,H34=I34,F34=I34, G34=I34, F34=H34) -> TRUE | N34: =AND(K34=FALSE,L34=FALSE,IF(COUNTIF(F34:I34,F34)>1,TRUE,FALSE),IF(COUNTIF(F34:I34,G34)>1,TRUE,FALSE),IF(COUNTIF(F34:I34,H34)>1,TRUE,FALSE),IF(COUNTIF(F34:I34,I34)>1,TRUE,FALSE)) -> FALSE | O34: =AND(N34=TRUE, COUNTIF(F34:I34, "100")) -> FALSE | P34: {=IFS(K34=TRUE, Q34, L34=TRUE, Q34, N34=FALSE, Q34, F34=G34, Q34, F34=Q34, Q34)} -> 2 | Q34: =MODE(F34:I34) -> 2
A35: 33 | B35: Alt Prime Rd. 1 | C35: 1 | D35: 20220505mouse5_OD_R_2_0_0000002_Structure_0001 | E35: https://drive.google.com/file/d/1faM5TBGGOymHJ2krVkMwj0-4hcMG7xPZ/view?usp=sharing | F35: 1 | G35: 1 | H35: 0.5 | I35: 1 | J35: =COUNTA(F35:I35) -> 4 | K35: {=IFS(OR(F35="",G35="",H35="",I35=""), FALSE, OR(F35<>G35, F35<>H35, F35<>I35, G35<>H35, G35<>I35, H35<>I35), FALSE, OR(F35=G35, F35=H35, F35=I35, G35=H35,G35=I35, H35=I35), TRUE)} -> FALSE | L35: =OR(AND(F35=G35,G35=H35),AND(H35=I35,F35=I35),AND(G35=H35,H35=I35), AND(F35=G35,G35=I35)) -> TRUE | M35: =OR(F35=G35,G35=H35,H35=I35,F35=I35, G35=I35, F35=H35) -> TRUE | N35: =AND(K35=FALSE,L35=FALSE,IF(COUNTIF(F35:I35,F35)>1,TRUE,FALSE),IF(COUNTIF(F35:I35,G35)>1,TRUE,FALSE),IF(COUNTIF(F35:I35,H35)>1,TRUE,FALSE),IF(COUNTIF(F35:I35,I35)>1,TRUE,FALSE)) -> FALSE | O35: =AND(N35=TRUE, COUNTIF(F35:I35, "100")) -> FALSE | P35: {=IFS(K35=TRUE, Q35, L35=TRUE, Q35, N35=FALSE, Q35, F35=G35, Q35, F35=Q35, Q35)} -> 1 | Q35: =MODE(F35:I35) -> 1
A36: 34 | B36: Alt Prime Rd. 1 | C36: 1 | D36: 20220505mouse5_OD_R_2_0_0000002_Structure_0002 | E36: https://drive.google.com/file/d/11tWjKdLMWE0uB9_Z7lZA2jjgzhhBg9lt/view?usp=sharing | F36: 100 | G36: 0.5 | H36: 0.5 | J36: =COUNTA(F36:I36) -> 3 | K36: {=IFS(OR(F36="",G36="",H36="",I36=""), FALSE, OR(F36<>G36, F36<>H36, F36<>I36, G36<>H36, G36<>I36, H36<>I36), FALSE, OR(F36=G36, F36=H36, F36=I36, G36=H36,G36=I36, H36=I36), TRUE)} -> FALSE | L36: =OR(AND(F36=G36,G36=H36),AND(H36=I36,F36=I36),AND(G36=H36,H36=I36), AND(F36=G36,G36=I36)) -> FALSE | M36: =OR(F36=G36,G36=H36,H36=I36,F36=I36, G36=I36, F36=H36) -> TRUE | N36: =AND(K36=FALSE,L36=FALSE,IF(COUNTIF(F36:I36,F36)>1,TRUE,FALSE),IF(COUNTIF(F36:I36,G36)>1,TRUE,FALSE),IF(COUNTIF(F36:I36,H36)>1,TRUE,FALSE),IF(COUNTIF(F36:I36,I36)>1,TRUE,FALSE)) -> FALSE | O36: =AND(N36=TRUE, COUNTIF(F36:I36, "100")) -> FALSE | P36: {=IFS(K36=TRUE, Q36, L36=TRUE, Q36, N36=FALSE, Q36, F36=G36, Q36, F36=Q36, Q36)} -> 0.5 | Q36: =MODE(F36:I36) -> 0.5
A37: 35 | B37: Alt Prime Rd. 1 | C37: 1 | D37: 20220505mouse5_OD_R_2_0_0000002_Structure_0003 | E37: https://drive.google.com/file/d/1tzli1BePGMAtDZKUrRc1wDNjrvVJ9-IY/view?usp=sharing | F37: 1 | G37: 0.5 | H37: 0.5 | I37: 1 | J37: =COUNTA(F37:I37) -> 4 | K37: {=IFS(OR(F37="",G37="",H37="",I37=""), FALSE, OR(F37<>G37, F37<>H37, F37<>I37, G37<>H37, G37<>I37, H37<>I37), FALSE, OR(F37=G37, F37=H37, F37=I37, G37=H37,G37=I37, H37=I37), TRUE)} -> FALSE | L37: =OR(AND(F37=G37,G37=H37),AND(H37=I37,F37=I37),AND(G37=H37,H37=I37), AND(F37=G37,G37=I37)) -> FALSE | M37: =OR(F37=G37,G37=H37,H37=I37,F37=I37, G37=I37, F37=H37) -> TRUE | N37: =AND(K37=FALSE,L37=FALSE,IF(COUNTIF(F37:I37,F37)>1,TRUE,FALSE),IF(COUNTIF(F37:I37,G37)>1,TRUE,FALSE),IF(COUNTIF(F37:I37,H37)>1,TRUE,FALSE),IF(COUNTIF(F37:I37,I37)>1,TRUE,FALSE)) -> TRUE | O37: =AND(N37=TRUE, COUNTIF(F37:I37, "100")) -> FALSE | P37: {=IFS(K37=TRUE, Q37, L37=TRUE, Q37, N37=FALSE, Q37, F37=G37, Q37, F37=Q37, Q37)} -> 1 | Q37: =MODE(F37:I37) -> 1
A38: 36 | B38: Alt Prime Rd. 1 | C38: 1 | D38: 20220505mouse5_OD_R_2_0_0000002_Structure_0004 | E38: https://drive.google.com/file/d/1DhHk_GEzzhbb1PeEd4YklDXjE8LBMAg3/view?usp=sharing | F38: 100 | H38: 100 | I38: 2 | J38: =COUNTA(F38:I38) -> 3 | K38: {=IFS(OR(F38="",G38="",H38="",I38=""), FALSE, OR(F38<>G38, F38<>H38, F38<>I38, G38<>H38, G38<>I38, H38<>I38), FALSE, OR(F38=G38, F38=H38, F38=I38, G38=H38,G38=I38, H38=I38), TRUE)} -> FALSE | L38: =OR(AND(F38=G38,G38=H38),AND(H38=I38,F38=I38),AND(G38=H38,H38=I38), AND(F38=G38,G38=I38)) -> FALSE | M38: =OR(F38=G38,G38=H38,H38=I38,F38=I38, G38=I38, F38=H38) -> TRUE | N38: =AND(K38=FALSE,L38=FALSE,IF(COUNTIF(F38:I38,F38)>1,TRUE,FALSE),IF(COUNTIF(F38:I38,G38)>1,TRUE,FALSE),IF(COUNTIF(F38:I38,H38)>1,TRUE,FALSE),IF(COUNTIF(F38:I38,I38)>1,TRUE,FALSE)) -> FALSE | O38: =AND(N38=TRUE, COUNTIF(F38:I38, "100")) -> FALSE | P38: {=IFS(K38=TRUE, Q38, L38=TRUE, Q38, N38=FALSE, Q38, F38=G38, Q38, F38=Q38, Q38)} -> 100 | Q38: =MODE(F38:I38) -> 100
A39: 37 | B39: Alt Prime Rd. 1 | C39: 1 | D39: 20220505mouse5_OD_R_4_0_0000009_Structure_0001 | E39: https://drive.google.com/file/d/1IqHg4-K-HFw_eHqbhcv_r7pqJAq18KpF/view?usp=sharing | F39: 2 | G39: 3 | H39: 3 | I39: 3 | J39: =COUNTA(F39:I39) -> 4 | K39: {=IFS(OR(F39="",G39="",H39="",I39=""), FALSE, OR(F39<>G39, F39<>H39, F39<>I39, G39<>H39, G39<>I39, H39<>I39), FALSE, OR(F39=G39, F39=H39, F39=I39, G39=H39,G39=I39, H39=I39), TRUE)} -> FALSE | L39: =OR(AND(F39=G39,G39=H39),AND(H39=I39,F39=I39),AND(G39=H39,H39=I39), AND(F39=G39,G39=I39)) -> TRUE | M39: =OR(F39=G39,G39=H39,H39=I39,F39=I39, G39=I39, F39=H39) -> TRUE | N39: =AND(K39=FALSE,L39=FALSE,IF(COUNTIF(F39:I39,F39)>1,TRUE,FALSE),IF(COUNTIF(F39:I39,G39)>1,TRUE,FALSE),IF(COUNTIF(F39:I39,H39)>1,TRUE,FALSE),IF(COUNTIF(F39:I39,I39)>1,TRUE,FALSE)) -> FALSE | O39: =AND(N39=TRUE, COUNTIF(F39:I39, "100")) -> FALSE | P39: {=IFS(K39=TRUE, Q39, L39=TRUE, Q39, N39=FALSE, Q39, F39=G39, Q39, F39=Q39, Q39)} -> 3 | Q39: =MODE(F39:I39) -> 3
A40: 38 | B40: Alt Prime Rd. 1 | C40: 1 | D40: 20220505mouse5_OD_R_4_0_0000009_Structure_0002 | E40: https://drive.google.com/file/d/1wnEKnkopKHmO3uSZZ7osMFa1D3tyo5ae/view?usp=sharing | F40: 3 | G40: 4 | H40: 4 | J40: =COUNTA(F40:I40) -> 3 | K40: {=IFS(OR(F40="",G40="",H40="",I40=""), FALSE, OR(F40<>G40, F40<>H40, F40<>I40, G40<>H40, G40<>I40, H40<>I40), FALSE, OR(F40=G40, F40=H40, F40=I40, G40=H40,G40=I40, H40=I40), TRUE)} -> FALSE | L40: =OR(AND(F40=G40,G40=H40),AND(H40=I40,F40=I40),AND(G40=H40,H40=I40), AND(F40=G40,G40=I40)) -> FALSE | M40: =OR(F40=G40,G40=H40,H40=I40,F40=I40, G40=I40, F40=H40) -> TRUE | N40: =AND(K40=FALSE,L40=FALSE,IF(COUNTIF(F40:I40,F40)>1,TRUE,FALSE),IF(COUNTIF(F40:I40,G40)>1,TRUE,FALSE),IF(COUNTIF(F40:I40,H40)>1,TRUE,FALSE),IF(COUNTIF(F40:I40,I40)>1,TRUE,FALSE)) -> FALSE | O40: =AND(N40=TRUE, COUNTIF(F40:I40, "100")) -> FALSE | P40: {=IFS(K40=TRUE, Q40, L40=TRUE, Q40, N40=FALSE, Q40, F40=G40, Q40, F40=Q40, Q40)} -> 4 | Q40: =MODE(F40:I40) -> 4
...

Sheet Score Tally
F2: ARVO Data | H2: Total w/ Score Sheet + ARVO
B3: Tally | C3: # Images/ Score | D3: PC Images (_2_) | E3: AC Images (_4_) | F3: ARVO - PC | G3: ARVO - AC | H3: PC | I3: AC
B4: Score 0 | C4: =COUNTIF('Score Sheet'!P:P,0) -> 1285 | D4: =COUNTIFS('Score Sheet'!P:P, "0",'Score Sheet'!D:D, "*_2_*") -> 474 | E4: =COUNTIFS('Score Sheet'!P:P, "0",'Score Sheet'!D:D,"*_4_*") -> 811 | F4: 206 | G4: 344 | H4: =SUM(D4,F4) -> 680 | I4: =sum(E4,G4) -> 1155
B5: Score 0.5 | C5: =COUNTIF('Score Sheet'!P:P,0.5) -> 759 | D5: =COUNTIFS('Score Sheet'!P:P, "0.5",'Score Sheet'!D:D, "*_2_*") -> 391 | E5: =COUNTIFS('Score Sheet'!P:P, "0.5",'Score Sheet'!D:D,"*_4_*") -> 368 | F5: 147 | G5: 131 | H5: =SUM(D5,F5) -> 538 | I5: =sum(E5,G5) -> 499
B6: Score 1 | C6: =COUNTIF('Score Sheet'!P:P,1) -> 596 | D6: =COUNTIFS('Score Sheet'!P:P, "1",'Score Sheet'!D:D, "*_2_*") -> 372 | E6: =COUNTIFS('Score Sheet'!P:P, "1",'Score Sheet'!D:D,"*_4_*") -> 224 | F6: 113 | G6: 140 | H6: =SUM(D6,F6) -> 485 | I6: =sum(E6,G6) -> 364
B7: Score 2 | C7: =COUNTIF('Score Sheet'!P:P,2) -> 650 | D7: =COUNTIFS('Score Sheet'!P:P, "2",'Score Sheet'!D:D, "*_2_*") -> 329 | E7: =COUNTIFS('Score Sheet'!P:P, "2",'Score Sheet'!D:D,"*_4_*") -> 321 | F7: 153 | G7: 128 | H7: =SUM(D7,F7) -> 482 | I7: =sum(E7,G7) -> 449
B8: Score 3 | C8: =COUNTIF('Score Sheet'!P:P,3) -> 294 | D8: =COUNTIFS('Score Sheet'!P:P, "3",'Score Sheet'!D:D, "*_2_*") -> 172 | E8: =COUNTIFS('Score Sheet'!P:P, "3",'Score Sheet'!D:D,"*_4_*") -> 122 | F8: 68 | G8: 63 | H8: =SUM(D8,F8) -> 240 | I8: =sum(E8,G8) -> 185
B9: Score 4 | C9: =COUNTIF('Score Sheet'!P:P,4) -> 219 | D9: =COUNTIFS('Score Sheet'!P:P, "4",'Score Sheet'!D:D, "*_2_*") -> 137 | E9: =COUNTIFS('Score Sheet'!P:P, "4",'Score Sheet'!D:D,"*_4_*") -> 82 | F9: 97 | G9: 63 | H9: =SUM(D9,F9) -> 234 | I9: =sum(E9,G9) -> 145
B10: Score n/a (100) | C10: =COUNTIF('Score Sheet'!P:P,100) -> 167 | D10: =COUNTIFS('Score Sheet'!P:P, "100",'Score Sheet'!D:D, "*_2_*") -> 136 | E10: =COUNTIFS('Score Sheet'!P:P, "100",'Score Sheet'!D:D,"*_4_*") -> 31 | F10: 24 | H10: =SUM(D10,F10) -> 160 | I10: =sum(E10,G10) -> 31
B11: Total: | C11: =SUM(C4:C10) -> 3970 | D11: =SUM(D4:D10) -> 2011 | E11: =SUM(E4:E10) -> 1959 | F11: =SUM(F4:F10) -> 808 | G11: =SUM(G4:G10) -> 869 | H11: =SUM(H4:H10) -> 2819 | I11: =SUM(I4:I10) -> 2828
F12: =sum(F11:G11) -> 1677
B13: AC/PC Sum: | C13: =SUM(D11:E11) -> 3970
B14: # Images Removed from Set | C14: 1

Sheet Text Only (NO formulas)
A1: Ordering | B1: Experiment Name | C1: Day of Experiment | D1: TIFF Name | E1: Link to Image | F1: KP score | G1: LW score | H1: KC score | I1: XP score | J1: # of Graders Scored | K1: 4/4 Graders Agree? | L1: 3/4 graders agree | M1: 2/4 graders agree | N1: 50/50 Split | O1: T/F if na of 50/50 Split | P1: Final Score | Q1: Mode | R1: Notes
A2: 0 | B2: 3971 | C2: 3971 | D2: 3971 | E2: 3971 | F2: 2128 | G2: 3928 | H2: 3670 | I2: 3127
A3: 1 | B3: Alt Prime Rd. 1 | C3: 1 | D3: 20220505mouse1_OD_R_2_0_0000002_Structure_0001D1 | E3: https://drive.google.com/file/d/16tNrWXMBbGIJLVTsPcJhp7jgVACRNegl/view?usp=sharing | F3: 2 | G3: 2 | H3: 2 | I3: 2 | J3: 4 | K3: TRUE | L3: TRUE | M3: TRUE | N3: FALSE | O3: FALSE | P3: 2 | Q3: 2
A4: 2 | B4: Alt Prime Rd. 1 | C4: 1 | D4: 20220505mouse1_OD_R_2_0_0000002_Structure_0002D1 | E4: https://drive.google.com/file/d/1E6yqvKyP7535UL_GEGFwMB_LsfavBr5p/view?usp=sharing | F4: 2 | G4: 2 | H4: 2 | I4: 2 | J4: 4 | K4: TRUE | L4: TRUE | M4: TRUE | N4: FALSE | O4: FALSE | P4: 2 | Q4: 2 | W4: ARVO Data | Y4: Total w/ Score Sheet + ARVO
A5: 3 | B5: Alt Prime Rd. 1 | C5: 1 | D5: 20220505mouse1_OD_R_2_0_0000002_Structure_0003D1 | E5: https://drive.google.com/file/d/1O76_BFFW5AhLFKfsdh3fRPvqEhQv1Vrg/view?usp=sharing | F5: 2 | G5: 2 | H5: 2 | I5: 2 | J5: 4 | K5: TRUE | L5: TRUE | M5: TRUE | N5: FALSE | O5: FALSE | P5: 2 | Q5: 2 | S5: Tally | T5: # Images/ Score | U5: PC Images (_2_) | V5: AC Images (_4_) | W5: ARVO - PC | X5: ARVO - AC | Y5: PC | Z5: AC
A6: 4 | B6: Alt Prime Rd. 1 | C6: 1 | D6: 20220505mouse1_OD_R_2_0_0000002_Structure_0004D1 | E6: https://drive.google.com/file/d/17InvZsVYM3wxw1CQ68Jj7U-6UGwp2CEY/view?usp=sharing | F6: 2 | G6: 2 | H6: 2 | I6: 2 | J6: 4 | K6: TRUE | L6: TRUE | M6: TRUE | N6: FALSE | O6: FALSE | P6: 2 | Q6: 2 | S6: Score 0 | T6: 1285 | U6: 474 | V6: 811 | W6: 206 | X6: 344 | Y6: 680 | Z6: 1155
A7: 5 | B7: Alt Prime Rd. 1 | C7: 1 | D7: 20220505mouse1_OD_R_4_0_0000009_Structure_0001D1 | E7: https://drive.google.com/file/d/1oQHTMcFO_RZ4HjMNfRzamPrpeFFis1oU/view?usp=sharing | F7: 1 | G7: 0.5 | H7: 1 | I7: 0.5 | J7: 4 | K7: FALSE | L7: FALSE | M7: TRUE | N7: TRUE | O7: FALSE | P7: 1 | Q7: 1 | S7: Score 0.5 | T7: 759 | U7: 391 | V7: 368 | W7: 147 | X7: 131 | Y7: 538 | Z7: 499
A8: 6 | B8: Alt Prime Rd. 1 | C8: 1 | D8: 20220505mouse1_OD_R_4_0_0000009_Structure_0002D1 | E8: https://drive.google.com/file/d/1mtU3TLB5IODf-xBWLZ_mPu35HQvsjrlb/view?usp=drive_link | F8: 1 | G8: 1 | H8: 1 | J8: 3 | K8: FALSE | L8: TRUE | M8: TRUE | N8: FALSE | O8: FALSE | P8: 1 | Q8: 1 | S8: Score 1 | T8: 596 | U8: 372 | V8: 224 | W8: 113 | X8: 140 | Y8: 485 | Z8: 364
A9: 7 | B9: Alt Prime Rd. 1 | C9: 1 | D9: 20220505mouse1_OD_R_4_0_0000009_Structure_0003D1 | E9: https://drive.google.com/file/d/1w_pQSRD31zRuvz49ekXdmLEfLlikcpf5/view?usp=sharing | F9: 2 | G9: 2 | H9: 1 | I9: 2 | J9: 4 | K9: FALSE | L9: TRUE | M9: TRUE | N9: FALSE | O9: FALSE | P9: 2 | Q9: 2 | S9: Score 2 | T9: 650 | U9: 329 | V9: 321 | W9: 153 | X9: 128 | Y9: 482 | Z9: 449
A10: 8 | B10: Alt Prime Rd. 1 | C10: 1 | D10: 20220505mouse1_OD_R_4_0_0000009_Structure_0004D1 | E10: https://drive.google.com/file/d/1MDZSz-goWbY9afJAjOb3JEZkQHdHt6qy/view?usp=drive_link | F10: 2 | G10: 2 | H10: 0.5 | J10: 3 | K10: FALSE | L10: FALSE | M10: TRUE | N10: FALSE | O10: FALSE | P10: 2 | Q10: 2 | S10: Score 3 | T10: 294 | U10: 172 | V10: 122 | W10: 68 | X10: 63 | Y10: 240 | Z10: 185
A11: 9 | B11: Alt Prime Rd. 1 | C11: 1 | D11: 20220505mouse2_OD_R_2_0_0000009_Structure_0001 | E11: https://drive.google.com/file/d/1_6p84kHnBbg8dqBRDHkadbBYQlexQBqf/view?usp=sharing | F11: 2 | G11: 2 | H11: 3 | I11: 2 | J11: 4 | K11: FALSE | L11: TRUE | M11: TRUE | N11: FALSE | O11: FALSE | P11: 2 | Q11: 2 | S11: Score 4 | T11: 219 | U11: 137 | V11: 82 | W11: 97 | X11: 63 | Y11: 234 | Z11: 145
A12: 10 | B12: Alt Prime Rd. 1 | C12: 1 | D12: 20220505mouse2_OD_R_2_0_0000009_Structure_0002 | E12: https://drive.google.com/file/d/1r0qbYe1s1sX2BP6kMRo3wQGGt8SldcpJ/view?usp=drive_link | F12: 1 | H12: 2 | I12: 2 | J12: 3 | K12: FALSE | L12: FALSE | M12: TRUE | N12: FALSE | O12: FALSE | P12: 2 | Q12: 2 | S12: Score n/a (100) | T12: 167 | U12: 136 | V12: 31 | W12: 24 | Y12: 160 | Z12: 31
A13: 11 | B13: Alt Prime Rd. 1 | C13: 1 | D13: 20220505mouse2_OD_R_2_0_0000009_Structure_0003 | E13: https://drive.google.com/file/d/1OWwwytHPsVPefD4v4iH9zfFsDETkq9gI/view?usp=sharing | F13: 1 | G13: 2 | H13: 2 | I13: 2 | J13: 4 | K13: FALSE | L13: TRUE | M13: TRUE | N13: FALSE | O13: FALSE | P13: 2 | Q13: 2 | S13: Total: | T13: 3970 | U13: 2011 | V13: 1959 | W13: 808 | X13: 869 | Y13: 2819 | Z13: 2828
A14: 12 | B14: Alt Prime Rd. 1 | C14: 1 | D14: 20220505mouse2_OD_R_2_0_0000009_Structure_0004 | E14: https://drive.google.com/file/d/1VS4YBP8KdMlY0qj8HFn4Xna0xnQI0R3y/view?usp=drive_link | F14: 1 | H14: 2 | I14: 2 | J14: 3 | K14: FALSE | L14: FALSE | M14: TRUE | N14: FALSE | O14: FALSE | P14: 2 | Q14: 2 | W14: 1677
A15: 13 | B15: Alt Prime Rd. 1 | C15: 1 | D15: 20220505mouse2_OD_R_4_0_0000002_Structure_0001 | E15: https://drive.google.com/file/d/1yZKIFNu1jW6bE0G39dtjcNpMuRffYG1A/view?usp=sharing | F15: 0.5 | G15: 0 | H15: 0.5 | I15: 0.5 | J15: 4 | K15: FALSE | L15: TRUE | M15: TRUE | N15: FALSE | O15: FALSE | P15: 0.5 | Q15: 0.5 | S15: AC/PC Sum: | T15: 3970
A16: 14 | B16: Alt Prime Rd. 1 | C16: 1 | D16: 20220505mouse2_OD_R_4_0_0000002_Structure_0002 | E16: https://drive.google.com/file/d/1xpltJOeFc5d-wI86cZFAHn4_XqTl2tdK/view?usp=drive_link | F16: 1 | G16: 1 | H16: 1 | J16: 3 | K16: FALSE | L16: TRUE | M16: TRUE | N16: FALSE | O16: FALSE | P16: 1 | Q16: 1 | S16: # Images Removed from Set | T16: 1
A17: 15 | B17: Alt Prime Rd. 1 | C17: 1 | D17: 20220505mouse2_OD_R_4_0_0000002_Structure_0003 | E17: https://drive.google.com/file/d/1zdeadoelUN17JRsqFP3WcgzPbPA-AOnJ/view?usp=sharing | F17: 1 | G17: 1 | H17: 1 | I17: 1 | J17: 4 | K17: TRUE | L17: TRUE | M17: TRUE | N17: FALSE | O17: FALSE | P17: 1 | Q17: 1
A18: 16 | B18: Alt Prime Rd. 1 | C18: 1 | D18: 20220505mouse2_OD_R_4_0_0000002_Structure_0004 | E18: https://drive.google.com/file/d/1SKyPcx3GJzBANF7XPkkzidkibfsCks1W/view?usp=drive_link | F18: 1 | H18: 1 | I18: 2 | J18: 3 | K18: FALSE | L18: FALSE | M18: TRUE | N18: FALSE | O18: FALSE | P18: 1 | Q18: 1
A19: 17 | B19: Alt Prime Rd. 1 | C19: 1 | D19: 20220505mouse3_OD_R_2_0_0000002_Structure_0001 | E19: https://drive.google.com/file/d/1xTQrAM-b-r4NccJ0sNKKjPfbl3oSPM-N/view?usp=sharing | F19: 2 | G19: 2 | H19: 1 | I19: 2 | J19: 4 | K19: FALSE | L19: TRUE | M19: TRUE | N19: FALSE | O19: FALSE | P19: 2 | Q19: 2
A20: 18 | B20: Alt Prime Rd. 1 | C20: 1 | D20: 20220505mouse3_OD_R_2_0_0000002_Structure_0002 | E20: https://drive.google.com/file/d/1PiFtlbmr6yUVjL6qOP18Kmi6ce-Z_z4Y/view?usp=drive_link | F20: 4 | H20: 3 | I20: 3 | J20: 3 | K20: FALSE | L20: FALSE | M20: TRUE | N20: FALSE | O20: FALSE | P20: 3 | Q20: 3
A21: 19 | B21: Alt Prime Rd. 1 | C21: 1 | D21: 20220505mouse3_OD_R_2_0_0000002_Structure_0003 | E21: https://drive.google.com/file/d/1iXrzQfODwMyqlmgL_I7lga8mbWs9L_d0/view?usp=sharing | F21: 2 | G21: 2 | H21: 1 | I21: 2 | J21: 4 | K21: FALSE | L21: TRUE | M21: TRUE | N21: FALSE | O21: FALSE | P21: 2 | Q21: 2
A22: 20 | B22: Alt Prime Rd. 1 | C22: 1 | D22: 20220505mouse3_OD_R_2_0_0000002_Structure_0004 | E22: https://drive.google.com/file/d/1-SUEa-DZB3j8dbqdMaKucMKllGFa1EJD/view?usp=drive_link | F22: 3 | H22: 2 | I22: 3 | J22: 3 | K22: FALSE | L22: FALSE | M22: TRUE | N22: FALSE | O22: FALSE | P22: 3 | Q22: 3
A23: 21 | B23: Alt Prime Rd. 1 | C23: 1 | D23: 20220505mouse3_OD_R_4_0_0000009_Structure_0001 | E23: https://drive.google.com/file/d/17qjPgEcJ5e3gy5gPhmQej30X-msf63_a/view?usp=sharing | F23: 2 | G23: 2 | H23: 2 | I23: 2 | J23: 4 | K23: TRUE | L23: TRUE | M23: TRUE | N23: FALSE | O23: FALSE | P23: 2 | Q23: 2
A24: 22 | B24: Alt Prime Rd. 1 | C24: 1 | D24: 20220505mouse3_OD_R_4_0_0000009_Structure_0002 | E24: https://drive.google.com/file/d/16r-t7RfkxHRA8VcOgl6n525cAgbUh5x9/view?usp=drive_link | F24: 2 | H24: 2 | I24: 1 | J24: 3 | K24: FALSE | L24: FALSE | M24: TRUE | N24: FALSE | O24: FALSE | P24: 2 | Q24: 2
A25: 23 | B25: Alt Prime Rd. 1 | C25: 1 | D25: 20220505mouse3_OD_R_4_0_0000009_Structure_0003 | E25: https://drive.google.com/file/d/1raAMPnEV5Y5010X9vXV1zrJsjTsJ3gqZ/view?usp=sharing | F25: 2 | G25: 2 | H25: 2 | I25: 2 | J25: 4 | K25: TRUE | L25: TRUE | M25: TRUE | N25: FALSE | O25: FALSE | P25: 2 | Q25: 2
A26: 24 | B26: Alt Prime Rd. 1 | C26: 1 | D26: 20220505mouse3_OD_R_4_0_0000009_Structure_0004 | E26: https://drive.google.com/file/d/1gGaGeMaALafEadsBB7ASw3nJMeqYyuZg/view?usp=drive_link | F26: 2 | G26: 2 | H26: 0.5 | J26: 3 | K26: FALSE | L26: FALSE | M26: TRUE | N26: FALSE | O26: FALSE | P26: 2 | Q26: 2
A27: 25 | B27: Alt Prime Rd. 1 | C27: 1 | D27: 20220505mouse4_OD_R_2_0_0000009_Structure_0001 | E27: https://drive.google.com/file/d/1P56qzOyJXvtnb-RIhmIHnmCYf8yZdgyQ/view?usp=sharing | F27: 0.5 | G27: 0.5 | H27: 0.5 | I27: 0.5 | J27: 4 | K27: TRUE | L27: TRUE | M27: TRUE | N27: FALSE | O27: FALSE | P27: 0.5 | Q27: 0.5
A28: 26 | B28: Alt Prime Rd. 1 | C28: 1 | D28: 20220505mouse4_OD_R_2_0_0000009_Structure_0002 | E28: https://drive.google.com/file/d/1MJBCK8iS0Iyqsfg7oiI3yAEkwlGHARur/view?usp=drive_link | F28: 0.5 | H28: 0.5 | I28: 1 | J28: 3 | K28: FALSE | L28: FALSE | M28: TRUE | N28: FALSE | O28: FALSE | P28: 0.5 | Q28: 0.5
A29: 27 | B29: Alt Prime Rd. 1 | C29: 1 | D29: 20220505mouse4_OD_R_2_0_0000009_Structure_0003 | E29: https://drive.google.com/file/d/1cONLD-kqJLlZw_tp_yMt6hcis2lPilO3/view?usp=sharing | F29: 0.5 | G29: 1 | H29: 0.5 | I29: 0.5 | J29: 4 | K29: FALSE | L29: TRUE | M29: TRUE | N29: FALSE | O29: FALSE | P29: 0.5 | Q29: 0.5
A30: 28 | B30: Alt Prime Rd. 1 | C30: 1 | D30: 20220505mouse4_OD_R_2_0_0000009_Structure_0004 | E30: https://drive.google.com/file/d/1Dm2MybyuwzVyzW3gtJhbtwvsdPdwyEO8/view?usp=drive_link | F30: 0.5 | G30: 0.5 | H30: 0.5 | J30: 3 | K30: FALSE | L30: TRUE | M30: TRUE | N30: FALSE | O30: FALSE | P30: 0.5 | Q30: 0.5
A31: 29 | B31: Alt Prime Rd. 1 | C31: 1 | D31: 20220505mouse4_OD_R_4_0_0000002_Structure_0001 | E31: https://drive.google.com/file/d/1NBa14fqiKm74YTxYugCidmiQblCmQSrn/view?usp=sharing | F31: 1 | G31: 1 | H31: 2 | I31: 1 | J31: 4 | K31: FALSE | L31: TRUE | M31: TRUE | N31: FALSE | O31: FALSE | P31: 1 | Q31: 1
A32: 30 | B32: Alt Prime Rd. 1 | C32: 1 | D32: 20220505mouse4_OD_R_4_0_0000002_Structure_0002 | E32: https://drive.google.com/file/d/1gs5T1vAiQ2wlBQaCRI0Bi-RUmZXTNKrf/view?usp=sharing | F32: 2 | H32: 2 | I32: 1 | J32: 3 | K32: FALSE | L32: FALSE | M32: TRUE | N32: FALSE | O32: FALSE | P32: 2 | Q32: 2
A33: 31 | B33: Alt Prime Rd. 1 | C33: 1 | D33: 20220505mouse4_OD_R_4_0_0000002_Structure_0003 | E33: https://drive.google.com/file/d/1QZvxNDBSGquzVytQVLYHsWCX_yg3CBmH/view?usp=sharing | F33: 2 | G33: 2 | H33: 3 | I33: 2 | J33: 4 | K33: FALSE | L33: TRUE | M33: TRUE | N33: FALSE | O33: FALSE | P33: 2 | Q33: 2
A34: 32 | B34: Alt Prime Rd. 1 | C34: 1 | D34: 20220505mouse4_OD_R_4_0_0000002_Structure_0004 | E34: https://drive.google.com/file/d/1PwXC271yZP_Gr5QLJgGjX7U8kFrvStMF/view?usp=sharing | F34: 2 | G34: 2 | H34: 2 | J34: 3 | K34: FALSE | L34: TRUE | M34: TRUE | N34: FALSE | O34: FALSE | P34: 2 | Q34: 2
A35: 33 | B35: Alt Prime Rd. 1 | C35: 1 | D35: 20220505mouse5_OD_R_2_0_0000002_Structure_0001 | E35: https://drive.google.com/file/d/1faM5TBGGOymHJ2krVkMwj0-4hcMG7xPZ/view?usp=sharing | F35: 1 | G35: 1 | H35: 0.5 | I35: 1 | J35: 4 | K35: FALSE | L35: TRUE | M35: TRUE | N35: FALSE | O35: FALSE | P35: 1 | Q35: 1
A36: 34 | B36: Alt Prime Rd. 1 | C36: 1 | D36: 20220505mouse5_OD_R_2_0_0000002_Structure_0002 | E36: https://drive.google.com/file/d/11tWjKdLMWE0uB9_Z7lZA2jjgzhhBg9lt/view?usp=sharing | F36: 100 | G36: 0.5 | H36: 0.5 | J36: 3 | K36: FALSE | L36: FALSE | M36: TRUE | N36: FALSE | O36: FALSE | P36: 0.5 | Q36: 0.5
A37: 35 | B37: Alt Prime Rd. 1 | C37: 1 | D37: 20220505mouse5_OD_R_2_0_0000002_Structure_0003 | E37: https://drive.google.com/file/d/1tzli1BePGMAtDZKUrRc1wDNjrvVJ9-IY/view?usp=sharing | F37: 1 | G37: 0.5 | H37: 0.5 | I37: 1 | J37: 4 | K37: FALSE | L37: FALSE | M37: TRUE | N37: TRUE | O37: FALSE | P37: 1 | Q37: 1
A38: 36 | B38: Alt Prime Rd. 1 | C38: 1 | D38: 20220505mouse5_OD_R_2_0_0000002_Structure_0004 | E38: https://drive.google.com/file/d/1DhHk_GEzzhbb1PeEd4YklDXjE8LBMAg3/view?usp=sharing | F38: 100 | H38: 100 | I38: 2 | J38: 3 | K38: FALSE | L38: FALSE | M38: TRUE | N38: FALSE | O38: FALSE | P38: 100 | Q38: 100
A39: 37 | B39: Alt Prime Rd. 1 | C39: 1 | D39: 20220505mouse5_OD_R_4_0_0000009_Structure_0001 | E39: https://drive.google.com/file/d/1IqHg4-K-HFw_eHqbhcv_r7pqJAq18KpF/view?usp=sharing | F39: 2 | G39: 3 | H39: 3 | I39: 3 | J39: 4 | K39: FALSE | L39: TRUE | M39: TRUE | N39: FALSE | O39: FALSE | P39: 3 | Q39: 3
A40: 38 | B40: Alt Prime Rd. 1 | C40: 1 | D40: 20220505mouse5_OD_R_4_0_0000009_Structure_0002 | E40: https://drive.google.com/file/d/1wnEKnkopKHmO3uSZZ7osMFa1D3tyo5ae/view?usp=sharing | F40: 3 | G40: 4 | H40: 4 | J40: 3 | K40: FALSE | L40: FALSE | M40: TRUE | N40: FALSE | O40: FALSE | P40: 4 | Q40: 4
...
